Workbook

Sheet Form responses 1
A1: Timestamp | B1: Order Number | C1: Customer Name | D1: ITeam Name | E1: Quentity
A2: 46151.443 | B2: 001 | C2: Kajal | D2: Watch | E2: 1
A3: 46151.448 | B3: 002 | C3: vinay | D3: shoes | E3: 2
A4: 46151.571 | B4: 003 | C4: sapna | D4: tumler | E4: 1
A5: 46152.604 | B5: 005 | C5: Binita | D5: Phone | E5: 1
A6: 46152.61 | B6: 78 | C6: sesharam | D6: fhfgh | E6: 20

Sheet FMS
A1: =NOW() -> 46153.661
A2: What | B2: Entery Event | F2: Check order | J2: Packing Order | N2: Deliver Order | R2: delivered confirmed ? | V2: Order Closed | Z2: Reattempt Delivery
A3: Who | B3: Paresh (sales/admin) | F3: Parkash | J3: Warehouse Staff | N3: Delivery Boy | R3: Delivery boy | V3: Admin | Z3: Delivery Boy
A4: How | B4: Order received | F4: Verify customer details, item, quantity | J4: Pick item, pack, label | N4: Delivery to Customer | R4: Take otp | V4: Remark complete order | Z4: Retry delivery
A5: When | B5: Whenever Needed | F5: 1 | J5: 1 | N5: 2 | R5: 0.5 | V5: 0 | Z5: 1
A6: Timestamp | B6: Order Number | C6: Customer Name | D6: ITeam Name | E6: Quentity | F6: Planned | G6: Actual | H6: Status | I6: Time Delay | J6: Planned | K6: Actual | L6: Status | M6: Time Delay | N6: Planned | O6: Actual | P6: Status | Q6: Time Delay | R6: Planned | S6: Actual | T6: Yes/No | U6: Time Delay | V6: Planned | W6: Actual | X6: Status | Y6: Time Delay | Z6: Planned | AA6: Actual | AB6: Status | AC6: Time Delay
A7: {=INDIRECT("'Form responses 1'!A2:E")} -> 46151.443 | B7: 001 | C7: Kajal | D7: Watch | E7: 1 | F7: =IF(OR(ISBLANK(A7),ISBLANK(F$5)),"",LET(_start,A7,_tat,F$5/24,_open,Config!$A$1,_close,Config!$A$2,_wd,Config!$A$3,_hol,Holidays!$A$1:$A$300,_sd,INT(_start),_st,MOD(_start,1),_iswd,_xlfn.WORKDAY.INTL(_sd-1,1,_wd,_hol)=_sd,_first,IF(_iswd,IF(_st<_open,_sd+_open,IF(_st>=_close,_xlfn.WORKDAY.INTL(_sd,1,_wd,_hol)+_open,_start)),_xlfn.WORKDAY.INTL(_sd,1,_wd,_hol)+_open),_ft,MOD(_first,1),_avail,_close - MAX(_ft,_open),IF(_tat<=_avail,_first + _tat,LET(_rem1,_tat - _avail,_daylen,_close - _open,_k,INT(_rem1/_daylen),_rem2,MOD(_rem1,_daylen),_base,_xlfn.WORKDAY.INTL(INT(_first),1+_k,_wd,_hol),IF(_rem2=0,_xlfn.WORKDAY.INTL(INT(_first),_k,_wd,_hol) + _close,_base + _open + _rem2))))) -> 46151.521 | G7: 46151.488 | H7: Done | I7: =IF(F7,IF(G7<>"",IF(G7>F7,G7-F7,""),$A$1-F7),"") | J7: =IF(OR(ISBLANK(G7),ISBLANK(J$5)),"",LET(_start,G7,_tat,J$5/24,_open,Config!$A$1,_close,Config!$A$2,_wd,Config!$A$3,_hol,Holidays!$A$1:$A$300,_sd,INT(_start),_st,MOD(_start,1),_iswd,_xlfn.WORKDAY.INTL(_sd-1,1,_wd,_hol)=_sd,_first,IF(_iswd,IF(_st<_open,_sd+_open,IF(_st>=_close,_xlfn.WORKDAY.INTL(_sd,1,_wd,_hol)+_open,_start)),_xlfn.WORKDAY.INTL(_sd,1,_wd,_hol)+_open),_ft,MOD(_first,1),_avail,_close - MAX(_ft,_open),IF(_tat<=_avail,_first + _tat,LET(_rem1,_tat - _avail,_daylen,_close - _open,_k,INT(_rem1/_daylen),_rem2,MOD(_rem1,_daylen),_base,_xlfn.WORKDAY.INTL(INT(_first),1+_k,_wd,_hol),IF(_rem2=0,_xlfn.WORKDAY.INTL(INT(_first),_k,_wd,_hol) + _close,_base + _open + _rem2))))) -> 46151.53 | K7: 46151.502 | L7: Done | M7: =IF(J7,IF(K7<>"",IF(K7>J7,K7-J7,""),$A$1-J7),"") | N7: =IF(OR(ISBLANK(K7),ISBLANK(N$5)),"",LET(_start,K7,_tat,N$5/24,_open,Config!$A$1,_close,Config!$A$2,_wd,Config!$A$3,_hol,Holidays!$A$1:$A$300,_sd,INT(_start),_st,MOD(_start,1),_iswd,_xlfn.WORKDAY.INTL(_sd-1,1,_wd,_hol)=_sd,_first,IF(_iswd,IF(_st<_open,_sd+_open,IF(_st>=_close,_xlfn.WORKDAY.INTL(_sd,1,_wd,_hol)+_open,_start)),_xlfn.WORKDAY.INTL(_sd,1,_wd,_hol)+_open),_ft,MOD(_first,1),_avail,_close - MAX(_ft,_open),IF(_tat<=_avail,_first + _tat,LET(_rem1,_tat - _avail,_daylen,_close - _open,_k,INT(_rem1/_daylen),_rem2,MOD(_rem1,_daylen),_base,_xlfn.WORKDAY.INTL(INT(_first),1+_k,_wd,_hol),IF(_rem2=0,_xlfn.WORKDAY.INTL(INT(_first),_k,_wd,_hol) + _close,_base + _open + _rem2))))) -> 46151.586 | O7: 46151.627 | P7: Done | Q7: =IF(N7,IF(O7<>"",IF(O7>N7,O7-N7,""),$A$1-N7),"") -> 0.041412384 | R7: =IF(OR(ISBLANK(O7),ISBLANK(R$5)),"",LET(_start,O7,_tat,R$5/24,_open,Config!$A$1,_close,Config!$A$2,_wd,Config!$A$3,_hol,Holidays!$A$1:$A$300,_sd,INT(_start),_st,MOD(_start,1),_iswd,_xlfn.WORKDAY.INTL(_sd-1,1,_wd,_hol)=_sd,_first,IF(_iswd,IF(_st<_open,_sd+_open,IF(_st>=_close,_xlfn.WORKDAY.INTL(_sd,1,_wd,_hol)+_open,_start)),_xlfn.WORKDAY.INTL(_sd,1,_wd,_hol)+_open),_ft,MOD(_first,1),_avail,_close - MAX(_ft,_open),IF(_tat<=_avail,_first + _tat,LET(_rem1,_tat - _avail,_daylen,_close - _open,_k,INT(_rem1/_daylen),_rem2,MOD(_rem1,_daylen),_base,_xlfn.WORKDAY.INTL(INT(_first),1+_k,_wd,_hol),IF(_rem2=0,_xlfn.WORKDAY.INTL(INT(_first),_k,_wd,_hol) + _close,_base + _open + _rem2))))) -> 46151.648 | S7: 46151.696 | T7: Yes | U7: =IF(R7,IF(S7<>"",IF(S7>R7,S7-R7,""),$A$1-R7),"") -> 0.047575278 | V7: =IF(T7="Yes",IF(OR(ISBLANK(S7),ISBLANK(V$5)),"",LET(_start,S7,_tat,V$5/24,_open,Config!$A$1,_close,Config!$A$2,_wd,Config!$A$3,_hol,Holidays!$A$1:$A$300,_sd,INT(_start),_st,MOD(_start,1),_iswd,_xlfn.WORKDAY.INTL(_sd-1,1,_wd,_hol)=_sd,_first,IF(_iswd,IF(_st<_open,_sd+_open,IF(_st>=_close,_xlfn.WORKDAY.INTL(_sd,1,_wd,_hol)+_open,_start)),_xlfn.WORKDAY.INTL(_sd,1,_wd,_hol)+_open),_ft,MOD(_first,1),_avail,_close - MAX(_ft,_open),IF(_tat<=_avail,_first + _tat,LET(_rem1,_tat - _avail,_daylen,_close - _open,_k,INT(_rem1/_daylen),_rem2,MOD(_rem1,_daylen),_base,_xlfn.WORKDAY.INTL(INT(_first),1+_k,_wd,_hol),IF(_rem2=0,_xlfn.WORKDAY.INTL(INT(_first),_k,_wd,_hol) + _close,_base + _open + _rem2))))),"") -> 46151.696 | W7: 46152.597 | X7: Done | Y7: =IF(V7,IF(W7<>"",IF(W7>V7,W7-V7,""),$A$1-V7),"") -> 0.90104601 | Z7: =IF(T7="No",IF(OR(ISBLANK(W7),ISBLANK(Z$5)),"",LET(_start,W7,_tat,Z$5/24,_open,Config!$A$1,_close,Config!$A$2,_wd,Config!$A$3,_hol,Holidays!$A$1:$A$300,_sd,INT(_start),_st,MOD(_start,1),_iswd,_xlfn.WORKDAY.INTL(_sd-1,1,_wd,_hol)=_sd,_first,IF(_iswd,IF(_st<_open,_sd+_open,IF(_st>=_close,_xlfn.WORKDAY.INTL(_sd,1,_wd,_hol)+_open,_start)),_xlfn.WORKDAY.INTL(_sd,1,_wd,_hol)+_open),_ft,MOD(_first,1),_avail,_close - MAX(_ft,_open),IF(_tat<=_avail,_first + _tat,LET(_rem1,_tat - _avail,_daylen,_close - _open,_k,INT(_rem1/_daylen),_rem2,MOD(_rem1,_daylen),_base,_xlfn.WORKDAY.INTL(INT(_first),1+_k,_wd,_hol),IF(_rem2=0,_xlfn.WORKDAY.INTL(INT(_first),_k,_wd,_hol) + _close,_base + _open + _rem2))))),"") | AC7: =IF(Z7,IF(AA7<>"",IF(AA7>Z7,AA7-Z7,""),$A$1-Z7),"")
A8: 46151.448 | B8: 002 | C8: vinay | D8: shoes | E8: 2 | F8: =IF(OR(ISBLANK(A8),ISBLANK(F$5)),"",LET(_start,A8,_tat,F$5/24,_open,Config!$A$1,_close,Config!$A$2,_wd,Config!$A$3,_hol,Holidays!$A$1:$A$300,_sd,INT(_start),_st,MOD(_start,1),_iswd,_xlfn.WORKDAY.INTL(_sd-1,1,_wd,_hol)=_sd,_first,IF(_iswd,IF(_st<_open,_sd+_open,IF(_st>=_close,_xlfn.WORKDAY.INTL(_sd,1,_wd,_hol)+_open,_start)),_xlfn.WORKDAY.INTL(_sd,1,_wd,_hol)+_open),_ft,MOD(_first,1),_avail,_close - MAX(_ft,_open),IF(_tat<=_avail,_first + _tat,LET(_rem1,_tat - _avail,_daylen,_close - _open,_k,INT(_rem1/_daylen),_rem2,MOD(_rem1,_daylen),_base,_xlfn.WORKDAY.INTL(INT(_first),1+_k,_wd,_hol),IF(_rem2=0,_xlfn.WORKDAY.INTL(INT(_first),_k,_wd,_hol) + _close,_base + _open + _rem2))))) -> 46151.521 | H8: Done | I8: =IF(F8,IF(G8<>"",IF(G8>F8,G8-F8,""),$A$1-F8),"") -> 2.1402825 | J8: =IF(OR(ISBLANK(G8),ISBLANK(J$5)),"",LET(_start,G8,_tat,J$5/24,_open,Config!$A$1,_close,Config!$A$2,_wd,Config!$A$3,_hol,Holidays!$A$1:$A$300,_sd,INT(_start),_st,MOD(_start,1),_iswd,_xlfn.WORKDAY.INTL(_sd-1,1,_wd,_hol)=_sd,_first,IF(_iswd,IF(_st<_open,_sd+_open,IF(_st>=_close,_xlfn.WORKDAY.INTL(_sd,1,_wd,_hol)+_open,_start)),_xlfn.WORKDAY.INTL(_sd,1,_wd,_hol)+_open),_ft,MOD(_first,1),_avail,_close - MAX(_ft,_open),IF(_tat<=_avail,_first + _tat,LET(_rem1,_tat - _avail,_daylen,_close - _open,_k,INT(_rem1/_daylen),_rem2,MOD(_rem1,_daylen),_base,_xlfn.WORKDAY.INTL(INT(_first),1+_k,_wd,_hol),IF(_rem2=0,_xlfn.WORKDAY.INTL(INT(_first),_k,_wd,_hol) + _close,_base + _open + _rem2))))) | K8: 46151.574 | L8: Done | M8: =IF(J8,IF(K8<>"",IF(K8>J8,K8-J8,""),$A$1-J8),"") | N8: =IF(OR(ISBLANK(K8),ISBLANK(N$5)),"",LET(_start,K8,_tat,N$5/24,_open,Config!$A$1,_close,Config!$A$2,_wd,Config!$A$3,_hol,Holidays!$A$1:$A$300,_sd,INT(_start),_st,MOD(_start,1),_iswd,_xlfn.WORKDAY.INTL(_sd-1,1,_wd,_hol)=_sd,_first,IF(_iswd,IF(_st<_open,_sd+_open,IF(_st>=_close,_xlfn.WORKDAY.INTL(_sd,1,_wd,_hol)+_open,_start)),_xlfn.WORKDAY.INTL(_sd,1,_wd,_hol)+_open),_ft,MOD(_first,1),_avail,_close - MAX(_ft,_open),IF(_tat<=_avail,_first + _tat,LET(_rem1,_tat - _avail,_daylen,_close - _open,_k,INT(_rem1/_daylen),_rem2,MOD(_rem1,_daylen),_base,_xlfn.WORKDAY.INTL(INT(_first),1+_k,_wd,_hol),IF(_rem2=0,_xlfn.WORKDAY.INTL(INT(_first),_k,_wd,_hol) + _close,_base + _open + _rem2))))) -> 46151.657 | O8: 46151.613 | P8: Done | Q8: =IF(N8,IF(O8<>"",IF(O8>N8,O8-N8,""),$A$1-N8),"") | R8: =IF(OR(ISBLANK(O8),ISBLANK(R$5)),"",LET(_start,O8,_tat,R$5/24,_open,Config!$A$1,_close,Config!$A$2,_wd,Config!$A$3,_hol,Holidays!$A$1:$A$300,_sd,INT(_start),_st,MOD(_start,1),_iswd,_xlfn.WORKDAY.INTL(_sd-1,1,_wd,_hol)=_sd,_first,IF(_iswd,IF(_st<_open,_sd+_open,IF(_st>=_close,_xlfn.WORKDAY.INTL(_sd,1,_wd,_hol)+_open,_start)),_xlfn.WORKDAY.INTL(_sd,1,_wd,_hol)+_open),_ft,MOD(_first,1),_avail,_close - MAX(_ft,_open),IF(_tat<=_avail,_first + _tat,LET(_rem1,_tat - _avail,_daylen,_close - _open,_k,INT(_rem1/_daylen),_rem2,MOD(_rem1,_daylen),_base,_xlfn.WORKDAY.INTL(INT(_first),1+_k,_wd,_hol),IF(_rem2=0,_xlfn.WORKDAY.INTL(INT(_first),_k,_wd,_hol) + _close,_base + _open + _rem2))))) -> 46151.634 | S8: 46151.695 | T8: No | U8: =IF(R8,IF(S8<>"",IF(S8>R8,S8-R8,""),$A$1-R8),"") -> 0.061368206 | V8: =IF(T8="Yes",IF(OR(ISBLANK(S8),ISBLANK(V$5)),"",LET(_start,S8,_tat,V$5/24,_open,Config!$A$1,_close,Config!$A$2,_wd,Config!$A$3,_hol,Holidays!$A$1:$A$300,_sd,INT(_start),_st,MOD(_start,1),_iswd,_xlfn.WORKDAY.INTL(_sd-1,1,_wd,_hol)=_sd,_first,IF(_iswd,IF(_st<_open,_sd+_open,IF(_st>=_close,_xlfn.WORKDAY.INTL(_sd,1,_wd,_hol)+_open,_start)),_xlfn.WORKDAY.INTL(_sd,1,_wd,_hol)+_open),_ft,MOD(_first,1),_avail,_close - MAX(_ft,_open),IF(_tat<=_avail,_first + _tat,LET(_rem1,_tat - _avail,_daylen,_close - _open,_k,INT(_rem1/_daylen),_rem2,MOD(_rem1,_daylen),_base,_xlfn.WORKDAY.INTL(INT(_first),1+_k,_wd,_hol),IF(_rem2=0,_xlfn.WORKDAY.INTL(INT(_first),_k,_wd,_hol) + _close,_base + _open + _rem2))))),"") | Y8: =IF(V8,IF(W8<>"",IF(W8>V8,W8-V8,""),$A$1-V8),"") | Z8: =IF(T8="No",IF(OR(ISBLANK(W8),ISBLANK(Z$5)),"",LET(_start,W8,_tat,Z$5/24,_open,Config!$A$1,_close,Config!$A$2,_wd,Config!$A$3,_hol,Holidays!$A$1:$A$300,_sd,INT(_start),_st,MOD(_start,1),_iswd,_xlfn.WORKDAY.INTL(_sd-1,1,_wd,_hol)=_sd,_first,IF(_iswd,IF(_st<_open,_sd+_open,IF(_st>=_close,_xlfn.WORKDAY.INTL(_sd,1,_wd,_hol)+_open,_start)),_xlfn.WORKDAY.INTL(_sd,1,_wd,_hol)+_open),_ft,MOD(_first,1),_avail,_close - MAX(_ft,_open),IF(_tat<=_avail,_first + _tat,LET(_rem1,_tat - _avail,_daylen,_close - _open,_k,INT(_rem1/_daylen),_rem2,MOD(_rem1,_daylen),_base,_xlfn.WORKDAY.INTL(INT(_first),1+_k,_wd,_hol),IF(_rem2=0,_xlfn.WORKDAY.INTL(INT(_first),_k,_wd,_hol) + _close,_base + _open + _rem2))))),"") | AC8: =IF(Z8,IF(AA8<>"",IF(AA8>Z8,AA8-Z8,""),$A$1-Z8),"")
A9: 46151.571 | B9: 003 | C9: sapna | D9: tumler | E9: 1 | F9: =IF(OR(ISBLANK(A9),ISBLANK(F$5)),"",LET(_start,A9,_tat,F$5/24,_open,Config!$A$1,_close,Config!$A$2,_wd,Config!$A$3,_hol,Holidays!$A$1:$A$300,_sd,INT(_start),_st,MOD(_start,1),_iswd,_xlfn.WORKDAY.INTL(_sd-1,1,_wd,_hol)=_sd,_first,IF(_iswd,IF(_st<_open,_sd+_open,IF(_st>=_close,_xlfn.WORKDAY.INTL(_sd,1,_wd,_hol)+_open,_start)),_xlfn.WORKDAY.INTL(_sd,1,_wd,_hol)+_open),_ft,MOD(_first,1),_avail,_close - MAX(_ft,_open),IF(_tat<=_avail,_first + _tat,LET(_rem1,_tat - _avail,_daylen,_close - _open,_k,INT(_rem1/_daylen),_rem2,MOD(_rem1,_daylen),_base,_xlfn.WORKDAY.INTL(INT(_first),1+_k,_wd,_hol),IF(_rem2=0,_xlfn.WORKDAY.INTL(INT(_first),_k,_wd,_hol) + _close,_base + _open + _rem2))))) -> 46151.613 | G9: 46151.627 | H9: Done | I9: =IF(F9,IF(G9<>"",IF(G9>F9,G9-F9,""),$A$1-F9),"") -> 0.014556366 | J9: =IF(OR(ISBLANK(G9),ISBLANK(J$5)),"",LET(_start,G9,_tat,J$5/24,_open,Config!$A$1,_close,Config!$A$2,_wd,Config!$A$3,_hol,Holidays!$A$1:$A$300,_sd,INT(_start),_st,MOD(_start,1),_iswd,_xlfn.WORKDAY.INTL(_sd-1,1,_wd,_hol)=_sd,_first,IF(_iswd,IF(_st<_open,_sd+_open,IF(_st>=_close,_xlfn.WORKDAY.INTL(_sd,1,_wd,_hol)+_open,_start)),_xlfn.WORKDAY.INTL(_sd,1,_wd,_hol)+_open),_ft,MOD(_first,1),_avail,_close - MAX(_ft,_open),IF(_tat<=_avail,_first + _tat,LET(_rem1,_tat - _avail,_daylen,_close - _open,_k,INT(_rem1/_daylen),_rem2,MOD(_rem1,_daylen),_base,_xlfn.WORKDAY.INTL(INT(_first),1+_k,_wd,_hol),IF(_rem2=0,_xlfn.WORKDAY.INTL(INT(_first),_k,_wd,_hol) + _close,_base + _open + _rem2))))) -> 46151.669 | K9: 46152.592 | L9: Done | M9: =IF(J9,IF(K9<>"",IF(K9>J9,K9-J9,""),$A$1-J9),"") -> 0.92241867 | N9: =IF(OR(ISBLANK(K9),ISBLANK(N$5)),"",LET(_start,K9,_tat,N$5/24,_open,Config!$A$1,_close,Config!$A$2,_wd,Config!$A$3,_hol,Holidays!$A$1:$A$300,_sd,INT(_start),_st,MOD(_start,1),_iswd,_xlfn.WORKDAY.INTL(_sd-1,1,_wd,_hol)=_sd,_first,IF(_iswd,IF(_st<_open,_sd+_open,IF(_st>=_close,_xlfn.WORKDAY.INTL(_sd,1,_wd,_hol)+_open,_start)),_xlfn.WORKDAY.INTL(_sd,1,_wd,_hol)+_open),_ft,MOD(_first,1),_avail,_close - MAX(_ft,_open),IF(_tat<=_avail,_first + _tat,LET(_rem1,_tat - _avail,_daylen,_close - _open,_k,INT(_rem1/_daylen),_rem2,MOD(_rem1,_daylen),_base,_xlfn.WORKDAY.INTL(INT(_first),1+_k,_wd,_hol),IF(_rem2=0,_xlfn.WORKDAY.INTL(INT(_first),_k,_wd,_hol) + _close,_base + _open + _rem2))))) -> 46153.562 | O9: 46152.598 | P9: Done | Q9: =IF(N9,IF(O9<>"",IF(O9>N9,O9-N9,""),$A$1-N9),"") | R9: =IF(OR(ISBLANK(O9),ISBLANK(R$5)),"",LET(_start,O9,_tat,R$5/24,_open,Config!$A$1,_close,Config!$A$2,_wd,Config!$A$3,_hol,Holidays!$A$1:$A$300,_sd,INT(_start),_st,MOD(_start,1),_iswd,_xlfn.WORKDAY.INTL(_sd-1,1,_wd,_hol)=_sd,_first,IF(_iswd,IF(_st<_open,_sd+_open,IF(_st>=_close,_xlfn.WORKDAY.INTL(_sd,1,_wd,_hol)+_open,_start)),_xlfn.WORKDAY.INTL(_sd,1,_wd,_hol)+_open),_ft,MOD(_first,1),_avail,_close - MAX(_ft,_open),IF(_tat<=_avail,_first + _tat,LET(_rem1,_tat - _avail,_daylen,_close - _open,_k,INT(_rem1/_daylen),_rem2,MOD(_rem1,_daylen),_base,_xlfn.WORKDAY.INTL(INT(_first),1+_k,_wd,_hol),IF(_rem2=0,_xlfn.WORKDAY.INTL(INT(_first),_k,_wd,_hol) + _close,_base + _open + _rem2))))) -> 46153.5 | S9: 46152.598 | T9: No | U9: =IF(R9,IF(S9<>"",IF(S9>R9,S9-R9,""),$A$1-R9),"") | V9: =IF(T9="Yes",IF(OR(ISBLANK(S9),ISBLANK(V$5)),"",LET(_start,S9,_tat,V$5/24,_open,Config!$A$1,_close,Config!$A$2,_wd,Config!$A$3,_hol,Holidays!$A$1:$A$300,_sd,INT(_start),_st,MOD(_start,1),_iswd,_xlfn.WORKDAY.INTL(_sd-1,1,_wd,_hol)=_sd,_first,IF(_iswd,IF(_st<_open,_sd+_open,IF(_st>=_close,_xlfn.WORKDAY.INTL(_sd,1,_wd,_hol)+_open,_start)),_xlfn.WORKDAY.INTL(_sd,1,_wd,_hol)+_open),_ft,MOD(_first,1),_avail,_close - MAX(_ft,_open),IF(_tat<=_avail,_first + _tat,LET(_rem1,_tat - _avail,_daylen,_close - _open,_k,INT(_rem1/_daylen),_rem2,MOD(_rem1,_daylen),_base,_xlfn.WORKDAY.INTL(INT(_first),1+_k,_wd,_hol),IF(_rem2=0,_xlfn.WORKDAY.INTL(INT(_first),_k,_wd,_hol) + _close,_base + _open + _rem2))))),"") | Y9: =IF(V9,IF(W9<>"",IF(W9>V9,W9-V9,""),$A$1-V9),"") | Z9: =IF(T9="No",IF(OR(ISBLANK(W9),ISBLANK(Z$5)),"",LET(_start,W9,_tat,Z$5/24,_open,Config!$A$1,_close,Config!$A$2,_wd,Config!$A$3,_hol,Holidays!$A$1:$A$300,_sd,INT(_start),_st,MOD(_start,1),_iswd,_xlfn.WORKDAY.INTL(_sd-1,1,_wd,_hol)=_sd,_first,IF(_iswd,IF(_st<_open,_sd+_open,IF(_st>=_close,_xlfn.WORKDAY.INTL(_sd,1,_wd,_hol)+_open,_start)),_xlfn.WORKDAY.INTL(_sd,1,_wd,_hol)+_open),_ft,MOD(_first,1),_avail,_close - MAX(_ft,_open),IF(_tat<=_avail,_first + _tat,LET(_rem1,_tat - _avail,_daylen,_close - _open,_k,INT(_rem1/_daylen),_rem2,MOD(_rem1,_daylen),_base,_xlfn.WORKDAY.INTL(INT(_first),1+_k,_wd,_hol),IF(_rem2=0,_xlfn.WORKDAY.INTL(INT(_first),_k,_wd,_hol) + _close,_base + _open + _rem2))))),"") | AC9: =IF(Z9,IF(AA9<>"",IF(AA9>Z9,AA9-Z9,""),$A$1-Z9),"")
A10: 46152.604 | B10: 005 | C10: Binita | D10: Phone | E10: 1 | F10: =IF(OR(ISBLANK(A10),ISBLANK(F$5)),"",LET(_start,A10,_tat,F$5/24,_open,Config!$A$1,_close,Config!$A$2,_wd,Config!$A$3,_hol,Holidays!$A$1:$A$300,_sd,INT(_start),_st,MOD(_start,1),_iswd,_xlfn.WORKDAY.INTL(_sd-1,1,_wd,_hol)=_sd,_first,IF(_iswd,IF(_st<_open,_sd+_open,IF(_st>=_close,_xlfn.WORKDAY.INTL(_sd,1,_wd,_hol)+_open,_start)),_xlfn.WORKDAY.INTL(_sd,1,_wd,_hol)+_open),_ft,MOD(_first,1),_avail,_close - MAX(_ft,_open),IF(_tat<=_avail,_first + _tat,LET(_rem1,_tat - _avail,_daylen,_close - _open,_k,INT(_rem1/_daylen),_rem2,MOD(_rem1,_daylen),_base,_xlfn.WORKDAY.INTL(INT(_first),1+_k,_wd,_hol),IF(_rem2=0,_xlfn.WORKDAY.INTL(INT(_first),_k,_wd,_hol) + _close,_base + _open + _rem2))))) -> 46153.521 | G10: 46152.606 | H10: Done | I10: =IF(F10,IF(G10<>"",IF(G10>F10,G10-F10,""),$A$1-F10),"") | J10: =IF(OR(ISBLANK(G10),ISBLANK(J$5)),"",LET(_start,G10,_tat,J$5/24,_open,Config!$A$1,_close,Config!$A$2,_wd,Config!$A$3,_hol,Holidays!$A$1:$A$300,_sd,INT(_start),_st,MOD(_start,1),_iswd,_xlfn.WORKDAY.INTL(_sd-1,1,_wd,_hol)=_sd,_first,IF(_iswd,IF(_st<_open,_sd+_open,IF(_st>=_close,_xlfn.WORKDAY.INTL(_sd,1,_wd,_hol)+_open,_start)),_xlfn.WORKDAY.INTL(_sd,1,_wd,_hol)+_open),_ft,MOD(_first,1),_avail,_close - MAX(_ft,_open),IF(_tat<=_avail,_first + _tat,LET(_rem1,_tat - _avail,_daylen,_close - _open,_k,INT(_rem1/_daylen),_rem2,MOD(_rem1,_daylen),_base,_xlfn.WORKDAY.INTL(INT(_first),1+_k,_wd,_hol),IF(_rem2=0,_xlfn.WORKDAY.INTL(INT(_first),_k,_wd,_hol) + _close,_base + _open + _rem2))))) -> 46153.521 | K10: 46152.607 | L10: Done | M10: =IF(J10,IF(K10<>"",IF(K10>J10,K10-J10,""),$A$1-J10),"") | N10: =IF(OR(ISBLANK(K10),ISBLANK(N$5)),"",LET(_start,K10,_tat,N$5/24,_open,Config!$A$1,_close,Config!$A$2,_wd,Config!$A$3,_hol,Holidays!$A$1:$A$300,_sd,INT(_start),_st,MOD(_start,1),_iswd,_xlfn.WORKDAY.INTL(_sd-1,1,_wd,_hol)=_sd,_first,IF(_iswd,IF(_st<_open,_sd+_open,IF(_st>=_close,_xlfn.WORKDAY.INTL(_sd,1,_wd,_hol)+_open,_start)),_xlfn.WORKDAY.INTL(_sd,1,_wd,_hol)+_open),_ft,MOD(_first,1),_avail,_close - MAX(_ft,_open),IF(_tat<=_avail,_first + _tat,LET(_rem1,_tat - _avail,_daylen,_close - _open,_k,INT(_rem1/_daylen),_rem2,MOD(_rem1,_daylen),_base,_xlfn.WORKDAY.INTL(INT(_first),1+_k,_wd,_hol),IF(_rem2=0,_xlfn.WORKDAY.INTL(INT(_first),_k,_wd,_hol) + _close,_base + _open + _rem2))))) -> 46153.562 | O10: 46152.608 | P10: Done | Q10: =IF(N10,IF(O10<>"",IF(O10>N10,O10-N10,""),$A$1-N10),"") | R10: =IF(OR(ISBLANK(O10),ISBLANK(R$5)),"",LET(_start,O10,_tat,R$5/24,_open,Config!$A$1,_close,Config!$A$2,_wd,Config!$A$3,_hol,Holidays!$A$1:$A$300,_sd,INT(_start),_st,MOD(_start,1),_iswd,_xlfn.WORKDAY.INTL(_sd-1,1,_wd,_hol)=_sd,_first,IF(_iswd,IF(_st<_open,_sd+_open,IF(_st>=_close,_xlfn.WORKDAY.INTL(_sd,1,_wd,_hol)+_open,_start)),_xlfn.WORKDAY.INTL(_sd,1,_wd,_hol)+_open),_ft,MOD(_first,1),_avail,_close - MAX(_ft,_open),IF(_tat<=_avail,_first + _tat,LET(_rem1,_tat - _avail,_daylen,_close - _open,_k,INT(_rem1/_daylen),_rem2,MOD(_rem1,_daylen),_base,_xlfn.WORKDAY.INTL(INT(_first),1+_k,_wd,_hol),IF(_rem2=0,_xlfn.WORKDAY.INTL(INT(_first),_k,_wd,_hol) + _close,_base + _open + _rem2))))) -> 46153.5 | S10: 46152.608 | T10: No | U10: =IF(R10,IF(S10<>"",IF(S10>R10,S10-R10,""),$A$1-R10),"") | V10: =IF(T10="Yes",IF(OR(ISBLANK(S10),ISBLANK(V$5)),"",LET(_start,S10,_tat,V$5/24,_open,Config!$A$1,_close,Config!$A$2,_wd,Config!$A$3,_hol,Holidays!$A$1:$A$300,_sd,INT(_start),_st,MOD(_start,1),_iswd,_xlfn.WORKDAY.INTL(_sd-1,1,_wd,_hol)=_sd,_first,IF(_iswd,IF(_st<_open,_sd+_open,IF(_st>=_close,_xlfn.WORKDAY.INTL(_sd,1,_wd,_hol)+_open,_start)),_xlfn.WORKDAY.INTL(_sd,1,_wd,_hol)+_open),_ft,MOD(_first,1),_avail,_close - MAX(_ft,_open),IF(_tat<=_avail,_first + _tat,LET(_rem1,_tat - _avail,_daylen,_close - _open,_k,INT(_rem1/_daylen),_rem2,MOD(_rem1,_daylen),_base,_xlfn.WORKDAY.INTL(INT(_first),1+_k,_wd,_hol),IF(_rem2=0,_xlfn.WORKDAY.INTL(INT(_first),_k,_wd,_hol) + _close,_base + _open + _rem2))))),"") | Y10: =IF(V10,IF(W10<>"",IF(W10>V10,W10-V10,""),$A$1-V10),"") | Z10: =IF(T10="No",IF(OR(ISBLANK(W10),ISBLANK(Z$5)),"",LET(_start,W10,_tat,Z$5/24,_open,Config!$A$1,_close,Config!$A$2,_wd,Config!$A$3,_hol,Holidays!$A$1:$A$300,_sd,INT(_start),_st,MOD(_start,1),_iswd,_xlfn.WORKDAY.INTL(_sd-1,1,_wd,_hol)=_sd,_first,IF(_iswd,IF(_st<_open,_sd+_open,IF(_st>=_close,_xlfn.WORKDAY.INTL(_sd,1,_wd,_hol)+_open,_start)),_xlfn.WORKDAY.INTL(_sd,1,_wd,_hol)+_open),_ft,MOD(_first,1),_avail,_close - MAX(_ft,_open),IF(_tat<=_avail,_first + _tat,LET(_rem1,_tat - _avail,_daylen,_close - _open,_k,INT(_rem1/_daylen),_rem2,MOD(_rem1,_daylen),_base,_xlfn.WORKDAY.INTL(INT(_first),1+_k,_wd,_hol),IF(_rem2=0,_xlfn.WORKDAY.INTL(INT(_first),_k,_wd,_hol) + _close,_base + _open + _rem2))))),"") | AC10: =IF(Z10,IF(AA10<>"",IF(AA10>Z10,AA10-Z10,""),$A$1-Z10),"")
A11: 46152.61 | B11: 78 | C11: sesharam | D11: fhfgh | E11: 20 | F11: =IF(OR(ISBLANK(A11),ISBLANK(F$5)),"",LET(_start,A11,_tat,F$5/24,_open,Config!$A$1,_close,Config!$A$2,_wd,Config!$A$3,_hol,Holidays!$A$1:$A$300,_sd,INT(_start),_st,MOD(_start,1),_iswd,_xlfn.WORKDAY.INTL(_sd-1,1,_wd,_hol)=_sd,_first,IF(_iswd,IF(_st<_open,_sd+_open,IF(_st>=_close,_xlfn.WORKDAY.INTL(_sd,1,_wd,_hol)+_open,_start)),_xlfn.WORKDAY.INTL(_sd,1,_wd,_hol)+_open),_ft,MOD(_first,1),_avail,_close - MAX(_ft,_open),IF(_tat<=_avail,_first + _tat,LET(_rem1,_tat - _avail,_daylen,_close - _open,_k,INT(_rem1/_daylen),_rem2,MOD(_rem1,_daylen),_base,_xlfn.WORKDAY.INTL(INT(_first),1+_k,_wd,_hol),IF(_rem2=0,_xlfn.WORKDAY.INTL(INT(_first),_k,_wd,_hol) + _close,_base + _open + _rem2))))) -> 46153.521 | G11: 46152.612 | H11: Done | I11: =IF(F11,IF(G11<>"",IF(G11>F11,G11-F11,""),$A$1-F11),"") | J11: =IF(OR(ISBLANK(G11),ISBLANK(J$5)),"",LET(_start,G11,_tat,J$5/24,_open,Config!$A$1,_close,Config!$A$2,_wd,Config!$A$3,_hol,Holidays!$A$1:$A$300,_sd,INT(_start),_st,MOD(_start,1),_iswd,_xlfn.WORKDAY.INTL(_sd-1,1,_wd,_hol)=_sd,_first,IF(_iswd,IF(_st<_open,_sd+_open,IF(_st>=_close,_xlfn.WORKDAY.INTL(_sd,1,_wd,_hol)+_open,_start)),_xlfn.WORKDAY.INTL(_sd,1,_wd,_hol)+_open),_ft,MOD(_first,1),_avail,_close - MAX(_ft,_open),IF(_tat<=_avail,_first + _tat,LET(_rem1,_tat - _avail,_daylen,_close - _open,_k,INT(_rem1/_daylen),_rem2,MOD(_rem1,_daylen),_base,_xlfn.WORKDAY.INTL(INT(_first),1+_k,_wd,_hol),IF(_rem2=0,_xlfn.WORKDAY.INTL(INT(_first),_k,_wd,_hol) + _close,_base + _open + _rem2))))) -> 46153.521 | M11: =IF(J11,IF(K11<>"",IF(K11>J11,K11-J11,""),$A$1-J11),"") -> 0.14028253 | N11: =IF(OR(ISBLANK(K11),ISBLANK(N$5)),"",LET(_start,K11,_tat,N$5/24,_open,Config!$A$1,_close,Config!$A$2,_wd,Config!$A$3,_hol,Holidays!$A$1:$A$300,_sd,INT(_start),_st,MOD(_start,1),_iswd,_xlfn.WORKDAY.INTL(_sd-1,1,_wd,_hol)=_sd,_first,IF(_iswd,IF(_st<_open,_sd+_open,IF(_st>=_close,_xlfn.WORKDAY.INTL(_sd,1,_wd,_hol)+_open,_start)),_xlfn.WORKDAY.INTL(_sd,1,_wd,_hol)+_open),_ft,MOD(_first,1),_avail,_close - MAX(_ft,_open),IF(_tat<=_avail,_first + _tat,LET(_rem1,_tat - _avail,_daylen,_close - _open,_k,INT(_rem1/_daylen),_rem2,MOD(_rem1,_daylen),_base,_xlfn.WORKDAY.INTL(INT(_first),1+_k,_wd,_hol),IF(_rem2=0,_xlfn.WORKDAY.INTL(INT(_first),_k,_wd,_hol) + _close,_base + _open + _rem2))))) | Q11: =IF(N11,IF(O11<>"",IF(O11>N11,O11-N11,""),$A$1-N11),"") | R11: =IF(OR(ISBLANK(O11),ISBLANK(R$5)),"",LET(_start,O11,_tat,R$5/24,_open,Config!$A$1,_close,Config!$A$2,_wd,Config!$A$3,_hol,Holidays!$A$1:$A$300,_sd,INT(_start),_st,MOD(_start,1),_iswd,_xlfn.WORKDAY.INTL(_sd-1,1,_wd,_hol)=_sd,_first,IF(_iswd,IF(_st<_open,_sd+_open,IF(_st>=_close,_xlfn.WORKDAY.INTL(_sd,1,_wd,_hol)+_open,_start)),_xlfn.WORKDAY.INTL(_sd,1,_wd,_hol)+_open),_ft,MOD(_first,1),_avail,_close - MAX(_ft,_open),IF(_tat<=_avail,_first + _tat,LET(_rem1,_tat - _avail,_daylen,_close - _open,_k,INT(_rem1/_daylen),_rem2,MOD(_rem1,_daylen),_base,_xlfn.WORKDAY.INTL(INT(_first),1+_k,_wd,_hol),IF(_rem2=0,_xlfn.WORKDAY.INTL(INT(_first),_k,_wd,_hol) + _close,_base + _open + _rem2))))) | U11: =IF(R11,IF(S11<>"",IF(S11>R11,S11-R11,""),$A$1-R11),"") | V11: =IF(T11="Yes",IF(OR(ISBLANK(S11),ISBLANK(V$5)),"",LET(_start,S11,_tat,V$5/24,_open,Config!$A$1,_close,Config!$A$2,_wd,Config!$A$3,_hol,Holidays!$A$1:$A$300,_sd,INT(_start),_st,MOD(_start,1),_iswd,_xlfn.WORKDAY.INTL(_sd-1,1,_wd,_hol)=_sd,_first,IF(_iswd,IF(_st<_open,_sd+_open,IF(_st>=_close,_xlfn.WORKDAY.INTL(_sd,1,_wd,_hol)+_open,_start)),_xlfn.WORKDAY.INTL(_sd,1,_wd,_hol)+_open),_ft,MOD(_first,1),_avail,_close - MAX(_ft,_open),IF(_tat<=_avail,_first + _tat,LET(_rem1,_tat - _avail,_daylen,_close - _open,_k,INT(_rem1/_daylen),_rem2,MOD(_rem1,_daylen),_base,_xlfn.WORKDAY.INTL(INT(_first),1+_k,_wd,_hol),IF(_rem2=0,_xlfn.WORKDAY.INTL(INT(_first),_k,_wd,_hol) + _close,_base + _open + _rem2))))),"") | Y11: =IF(V11,IF(W11<>"",IF(W11>V11,W11-V11,""),$A$1-V11),"") | Z11: =IF(T11="No",IF(OR(ISBLANK(W11),ISBLANK(Z$5)),"",LET(_start,W11,_tat,Z$5/24,_open,Config!$A$1,_close,Config!$A$2,_wd,Config!$A$3,_hol,Holidays!$A$1:$A$300,_sd,INT(_start),_st,MOD(_start,1),_iswd,_xlfn.WORKDAY.INTL(_sd-1,1,_wd,_hol)=_sd,_first,IF(_iswd,IF(_st<_open,_sd+_open,IF(_st>=_close,_xlfn.WORKDAY.INTL(_sd,1,_wd,_hol)+_open,_start)),_xlfn.WORKDAY.INTL(_sd,1,_wd,_hol)+_open),_ft,MOD(_first,1),_avail,_close - MAX(_ft,_open),IF(_tat<=_avail,_first + _tat,LET(_rem1,_tat - _avail,_daylen,_close - _open,_k,INT(_rem1/_daylen),_rem2,MOD(_rem1,_daylen),_base,_xlfn.WORKDAY.INTL(INT(_first),1+_k,_wd,_hol),IF(_rem2=0,_xlfn.WORKDAY.INTL(INT(_first),_k,_wd,_hol) + _close,_base + _open + _rem2))))),"") | AC11: =IF(Z11,IF(AA11<>"",IF(AA11>Z11,AA11-Z11,""),$A$1-Z11),"")
F12: =IF(OR(ISBLANK(A12),ISBLANK(F$5)),"",LET(_start,A12,_tat,F$5/24,_open,Config!$A$1,_close,Config!$A$2,_wd,Config!$A$3,_hol,Holidays!$A$1:$A$300,_sd,INT(_start),_st,MOD(_start,1),_iswd,_xlfn.WORKDAY.INTL(_sd-1,1,_wd,_hol)=_sd,_first,IF(_iswd,IF(_st<_open,_sd+_open,IF(_st>=_close,_xlfn.WORKDAY.INTL(_sd,1,_wd,_hol)+_open,_start)),_xlfn.WORKDAY.INTL(_sd,1,_wd,_hol)+_open),_ft,MOD(_first,1),_avail,_close - MAX(_ft,_open),IF(_tat<=_avail,_first + _tat,LET(_rem1,_tat - _avail,_daylen,_close - _open,_k,INT(_rem1/_daylen),_rem2,MOD(_rem1,_daylen),_base,_xlfn.WORKDAY.INTL(INT(_first),1+_k,_wd,_hol),IF(_rem2=0,_xlfn.WORKDAY.INTL(INT(_first),_k,_wd,_hol) + _close,_base + _open + _rem2))))) | I12: =IF(F12,IF(G12<>"",IF(G12>F12,G12-F12,""),$A$1-F12),"") | J12: =IF(OR(ISBLANK(G12),ISBLANK(J$5)),"",LET(_start,G12,_tat,J$5/24,_open,Config!$A$1,_close,Config!$A$2,_wd,Config!$A$3,_hol,Holidays!$A$1:$A$300,_sd,INT(_start),_st,MOD(_start,1),_iswd,_xlfn.WORKDAY.INTL(_sd-1,1,_wd,_hol)=_sd,_first,IF(_iswd,IF(_st<_open,_sd+_open,IF(_st>=_close,_xlfn.WORKDAY.INTL(_sd,1,_wd,_hol)+_open,_start)),_xlfn.WORKDAY.INTL(_sd,1,_wd,_hol)+_open),_ft,MOD(_first,1),_avail,_close - MAX(_ft,_open),IF(_tat<=_avail,_first + _tat,LET(_rem1,_tat - _avail,_daylen,_close - _open,_k,INT(_rem1/_daylen),_rem2,MOD(_rem1,_daylen),_base,_xlfn.WORKDAY.INTL(INT(_first),1+_k,_wd,_hol),IF(_rem2=0,_xlfn.WORKDAY.INTL(INT(_first),_k,_wd,_hol) + _close,_base + _open + _rem2))))) | M12: =IF(J12,IF(K12<>"",IF(K12>J12,K12-J12,""),$A$1-J12),"") | N12: =IF(OR(ISBLANK(K12),ISBLANK(N$5)),"",LET(_start,K12,_tat,N$5/24,_open,Config!$A$1,_close,Config!$A$2,_wd,Config!$A$3,_hol,Holidays!$A$1:$A$300,_sd,INT(_start),_st,MOD(_start,1),_iswd,_xlfn.WORKDAY.INTL(_sd-1,1,_wd,_hol)=_sd,_first,IF(_iswd,IF(_st<_open,_sd+_open,IF(_st>=_close,_xlfn.WORKDAY.INTL(_sd,1,_wd,_hol)+_open,_start)),_xlfn.WORKDAY.INTL(_sd,1,_wd,_hol)+_open),_ft,MOD(_first,1),_avail,_close - MAX(_ft,_open),IF(_tat<=_avail,_first + _tat,LET(_rem1,_tat - _avail,_daylen,_close - _open,_k,INT(_rem1/_daylen),_rem2,MOD(_rem1,_daylen),_base,_xlfn.WORKDAY.INTL(INT(_first),1+_k,_wd,_hol),IF(_rem2=0,_xlfn.WORKDAY.INTL(INT(_first),_k,_wd,_hol) + _close,_base + _open + _rem2))))) | Q12: =IF(N12,IF(O12<>"",IF(O12>N12,O12-N12,""),$A$1-N12),"") | R12: =IF(OR(ISBLANK(O12),ISBLANK(R$5)),"",LET(_start,O12,_tat,R$5/24,_open,Config!$A$1,_close,Config!$A$2,_wd,Config!$A$3,_hol,Holidays!$A$1:$A$300,_sd,INT(_start),_st,MOD(_start,1),_iswd,_xlfn.WORKDAY.INTL(_sd-1,1,_wd,_hol)=_sd,_first,IF(_iswd,IF(_st<_open,_sd+_open,IF(_st>=_close,_xlfn.WORKDAY.INTL(_sd,1,_wd,_hol)+_open,_start)),_xlfn.WORKDAY.INTL(_sd,1,_wd,_hol)+_open),_ft,MOD(_first,1),_avail,_close - MAX(_ft,_open),IF(_tat<=_avail,_first + _tat,LET(_rem1,_tat - _avail,_daylen,_close - _open,_k,INT(_rem1/_daylen),_rem2,MOD(_rem1,_daylen),_base,_xlfn.WORKDAY.INTL(INT(_first),1+_k,_wd,_hol),IF(_rem2=0,_xlfn.WORKDAY.INTL(INT(_first),_k,_wd,_hol) + _close,_base + _open + _rem2))))) | U12: =IF(R12,IF(S12<>"",IF(S12>R12,S12-R12,""),$A$1-R12),"") | V12: =IF(T12="Yes",IF(OR(ISBLANK(S12),ISBLANK(V$5)),"",LET(_start,S12,_tat,V$5/24,_open,Config!$A$1,_close,Config!$A$2,_wd,Config!$A$3,_hol,Holidays!$A$1:$A$300,_sd,INT(_start),_st,MOD(_start,1),_iswd,_xlfn.WORKDAY.INTL(_sd-1,1,_wd,_hol)=_sd,_first,IF(_iswd,IF(_st<_open,_sd+_open,IF(_st>=_close,_xlfn.WORKDAY.INTL(_sd,1,_wd,_hol)+_open,_start)),_xlfn.WORKDAY.INTL(_sd,1,_wd,_hol)+_open),_ft,MOD(_first,1),_avail,_close - MAX(_ft,_open),IF(_tat<=_avail,_first + _tat,LET(_rem1,_tat - _avail,_daylen,_close - _open,_k,INT(_rem1/_daylen),_rem2,MOD(_rem1,_daylen),_base,_xlfn.WORKDAY.INTL(INT(_first),1+_k,_wd,_hol),IF(_rem2=0,_xlfn.WORKDAY.INTL(INT(_first),_k,_wd,_hol) + _close,_base + _open + _rem2))))),"") | Y12: =IF(V12,IF(W12<>"",IF(W12>V12,W12-V12,""),$A$1-V12),"") | Z12: =IF(T12="No",IF(OR(ISBLANK(W12),ISBLANK(Z$5)),"",LET(_start,W12,_tat,Z$5/24,_open,Config!$A$1,_close,Config!$A$2,_wd,Config!$A$3,_hol,Holidays!$A$1:$A$300,_sd,INT(_start),_st,MOD(_start,1),_iswd,_xlfn.WORKDAY.INTL(_sd-1,1,_wd,_hol)=_sd,_first,IF(_iswd,IF(_st<_open,_sd+_open,IF(_st>=_close,_xlfn.WORKDAY.INTL(_sd,1,_wd,_hol)+_open,_start)),_xlfn.WORKDAY.INTL(_sd,1,_wd,_hol)+_open),_ft,MOD(_first,1),_avail,_close - MAX(_ft,_open),IF(_tat<=_avail,_first + _tat,LET(_rem1,_tat - _avail,_daylen,_close - _open,_k,INT(_rem1/_daylen),_rem2,MOD(_rem1,_daylen),_base,_xlfn.WORKDAY.INTL(INT(_first),1+_k,_wd,_hol),IF(_rem2=0,_xlfn.WORKDAY.INTL(INT(_first),_k,_wd,_hol) + _close,_base + _open + _rem2))))),"") | AC12: =IF(Z12,IF(AA12<>"",IF(AA12>Z12,AA12-Z12,""),$A$1-Z12),"")
F13: =IF(OR(ISBLANK(A13),ISBLANK(F$5)),"",LET(_start,A13,_tat,F$5/24,_open,Config!$A$1,_close,Config!$A$2,_wd,Config!$A$3,_hol,Holidays!$A$1:$A$300,_sd,INT(_start),_st,MOD(_start,1),_iswd,_xlfn.WORKDAY.INTL(_sd-1,1,_wd,_hol)=_sd,_first,IF(_iswd,IF(_st<_open,_sd+_open,IF(_st>=_close,_xlfn.WORKDAY.INTL(_sd,1,_wd,_hol)+_open,_start)),_xlfn.WORKDAY.INTL(_sd,1,_wd,_hol)+_open),_ft,MOD(_first,1),_avail,_close - MAX(_ft,_open),IF(_tat<=_avail,_first + _tat,LET(_rem1,_tat - _avail,_daylen,_close - _open,_k,INT(_rem1/_daylen),_rem2,MOD(_rem1,_daylen),_base,_xlfn.WORKDAY.INTL(INT(_first),1+_k,_wd,_hol),IF(_rem2=0,_xlfn.WORKDAY.INTL(INT(_first),_k,_wd,_hol) + _close,_base + _open + _rem2))))) | I13: =IF(F13,IF(G13<>"",IF(G13>F13,G13-F13,""),$A$1-F13),"") | J13: =IF(OR(ISBLANK(G13),ISBLANK(J$5)),"",LET(_start,G13,_tat,J$5/24,_open,Config!$A$1,_close,Config!$A$2,_wd,Config!$A$3,_hol,Holidays!$A$1:$A$300,_sd,INT(_start),_st,MOD(_start,1),_iswd,_xlfn.WORKDAY.INTL(_sd-1,1,_wd,_hol)=_sd,_first,IF(_iswd,IF(_st<_open,_sd+_open,IF(_st>=_close,_xlfn.WORKDAY.INTL(_sd,1,_wd,_hol)+_open,_start)),_xlfn.WORKDAY.INTL(_sd,1,_wd,_hol)+_open),_ft,MOD(_first,1),_avail,_close - MAX(_ft,_open),IF(_tat<=_avail,_first + _tat,LET(_rem1,_tat - _avail,_daylen,_close - _open,_k,INT(_rem1/_daylen),_rem2,MOD(_rem1,_daylen),_base,_xlfn.WORKDAY.INTL(INT(_first),1+_k,_wd,_hol),IF(_rem2=0,_xlfn.WORKDAY.INTL(INT(_first),_k,_wd,_hol) + _close,_base + _open + _rem2))))) | M13: =IF(J13,IF(K13<>"",IF(K13>J13,K13-J13,""),$A$1-J13),"") | N13: =IF(OR(ISBLANK(K13),ISBLANK(N$5)),"",LET(_start,K13,_tat,N$5/24,_open,Config!$A$1,_close,Config!$A$2,_wd,Config!$A$3,_hol,Holidays!$A$1:$A$300,_sd,INT(_start),_st,MOD(_start,1),_iswd,_xlfn.WORKDAY.INTL(_sd-1,1,_wd,_hol)=_sd,_first,IF(_iswd,IF(_st<_open,_sd+_open,IF(_st>=_close,_xlfn.WORKDAY.INTL(_sd,1,_wd,_hol)+_open,_start)),_xlfn.WORKDAY.INTL(_sd,1,_wd,_hol)+_open),_ft,MOD(_first,1),_avail,_close - MAX(_ft,_open),IF(_tat<=_avail,_first + _tat,LET(_rem1,_tat - _avail,_daylen,_close - _open,_k,INT(_rem1/_daylen),_rem2,MOD(_rem1,_daylen),_base,_xlfn.WORKDAY.INTL(INT(_first),1+_k,_wd,_hol),IF(_rem2=0,_xlfn.WORKDAY.INTL(INT(_first),_k,_wd,_hol) + _close,_base + _open + _rem2))))) | Q13: =IF(N13,IF(O13<>"",IF(O13>N13,O13-N13,""),$A$1-N13),"") | R13: =IF(OR(ISBLANK(O13),ISBLANK(R$5)),"",LET(_start,O13,_tat,R$5/24,_open,Config!$A$1,_close,Config!$A$2,_wd,Config!$A$3,_hol,Holidays!$A$1:$A$300,_sd,INT(_start),_st,MOD(_start,1),_iswd,_xlfn.WORKDAY.INTL(_sd-1,1,_wd,_hol)=_sd,_first,IF(_iswd,IF(_st<_open,_sd+_open,IF(_st>=_close,_xlfn.WORKDAY.INTL(_sd,1,_wd,_hol)+_open,_start)),_xlfn.WORKDAY.INTL(_sd,1,_wd,_hol)+_open),_ft,MOD(_first,1),_avail,_close - MAX(_ft,_open),IF(_tat<=_avail,_first + _tat,LET(_rem1,_tat - _avail,_daylen,_close - _open,_k,INT(_rem1/_daylen),_rem2,MOD(_rem1,_daylen),_base,_xlfn.WORKDAY.INTL(INT(_first),1+_k,_wd,_hol),IF(_rem2=0,_xlfn.WORKDAY.INTL(INT(_first),_k,_wd,_hol) + _close,_base + _open + _rem2))))) | U13: =IF(R13,IF(S13<>"",IF(S13>R13,S13-R13,""),$A$1-R13),"") | V13: =IF(T13="Yes",IF(OR(ISBLANK(S13),ISBLANK(V$5)),"",LET(_start,S13,_tat,V$5/24,_open,Config!$A$1,_close,Config!$A$2,_wd,Config!$A$3,_hol,Holidays!$A$1:$A$300,_sd,INT(_start),_st,MOD(_start,1),_iswd,_xlfn.WORKDAY.INTL(_sd-1,1,_wd,_hol)=_sd,_first,IF(_iswd,IF(_st<_open,_sd+_open,IF(_st>=_close,_xlfn.WORKDAY.INTL(_sd,1,_wd,_hol)+_open,_start)),_xlfn.WORKDAY.INTL(_sd,1,_wd,_hol)+_open),_ft,MOD(_first,1),_avail,_close - MAX(_ft,_open),IF(_tat<=_avail,_first + _tat,LET(_rem1,_tat - _avail,_daylen,_close - _open,_k,INT(_rem1/_daylen),_rem2,MOD(_rem1,_daylen),_base,_xlfn.WORKDAY.INTL(INT(_first),1+_k,_wd,_hol),IF(_rem2=0,_xlfn.WORKDAY.INTL(INT(_first),_k,_wd,_hol) + _close,_base + _open + _rem2))))),"") | Y13: =IF(V13,IF(W13<>"",IF(W13>V13,W13-V13,""),$A$1-V13),"") | Z13: =IF(T13="No",IF(OR(ISBLANK(W13),ISBLANK(Z$5)),"",LET(_start,W13,_tat,Z$5/24,_open,Config!$A$1,_close,Config!$A$2,_wd,Config!$A$3,_hol,Holidays!$A$1:$A$300,_sd,INT(_start),_st,MOD(_start,1),_iswd,_xlfn.WORKDAY.INTL(_sd-1,1,_wd,_hol)=_sd,_first,IF(_iswd,IF(_st<_open,_sd+_open,IF(_st>=_close,_xlfn.WORKDAY.INTL(_sd,1,_wd,_hol)+_open,_start)),_xlfn.WORKDAY.INTL(_sd,1,_wd,_hol)+_open),_ft,MOD(_first,1),_avail,_close - MAX(_ft,_open),IF(_tat<=_avail,_first + _tat,LET(_rem1,_tat - _avail,_daylen,_close - _open,_k,INT(_rem1/_daylen),_rem2,MOD(_rem1,_daylen),_base,_xlfn.WORKDAY.INTL(INT(_first),1+_k,_wd,_hol),IF(_rem2=0,_xlfn.WORKDAY.INTL(INT(_first),_k,_wd,_hol) + _close,_base + _open + _rem2))))),"") | AC13: =IF(Z13,IF(AA13<>"",IF(AA13>Z13,AA13-Z13,""),$A$1-Z13),"")
F14: =IF(OR(ISBLANK(A14),ISBLANK(F$5)),"",LET(_start,A14,_tat,F$5/24,_open,Config!$A$1,_close,Config!$A$2,_wd,Config!$A$3,_hol,Holidays!$A$1:$A$300,_sd,INT(_start),_st,MOD(_start,1),_iswd,_xlfn.WORKDAY.INTL(_sd-1,1,_wd,_hol)=_sd,_first,IF(_iswd,IF(_st<_open,_sd+_open,IF(_st>=_close,_xlfn.WORKDAY.INTL(_sd,1,_wd,_hol)+_open,_start)),_xlfn.WORKDAY.INTL(_sd,1,_wd,_hol)+_open),_ft,MOD(_first,1),_avail,_close - MAX(_ft,_open),IF(_tat<=_avail,_first + _tat,LET(_rem1,_tat - _avail,_daylen,_close - _open,_k,INT(_rem1/_daylen),_rem2,MOD(_rem1,_daylen),_base,_xlfn.WORKDAY.INTL(INT(_first),1+_k,_wd,_hol),IF(_rem2=0,_xlfn.WORKDAY.INTL(INT(_first),_k,_wd,_hol) + _close,_base + _open + _rem2))))) | I14: =IF(F14,IF(G14<>"",IF(G14>F14,G14-F14,""),$A$1-F14),"") | J14: =IF(OR(ISBLANK(G14),ISBLANK(J$5)),"",LET(_start,G14,_tat,J$5/24,_open,Config!$A$1,_close,Config!$A$2,_wd,Config!$A$3,_hol,Holidays!$A$1:$A$300,_sd,INT(_start),_st,MOD(_start,1),_iswd,_xlfn.WORKDAY.INTL(_sd-1,1,_wd,_hol)=_sd,_first,IF(_iswd,IF(_st<_open,_sd+_open,IF(_st>=_close,_xlfn.WORKDAY.INTL(_sd,1,_wd,_hol)+_open,_start)),_xlfn.WORKDAY.INTL(_sd,1,_wd,_hol)+_open),_ft,MOD(_first,1),_avail,_close - MAX(_ft,_open),IF(_tat<=_avail,_first + _tat,LET(_rem1,_tat - _avail,_daylen,_close - _open,_k,INT(_rem1/_daylen),_rem2,MOD(_rem1,_daylen),_base,_xlfn.WORKDAY.INTL(INT(_first),1+_k,_wd,_hol),IF(_rem2=0,_xlfn.WORKDAY.INTL(INT(_first),_k,_wd,_hol) + _close,_base + _open + _rem2))))) | M14: =IF(J14,IF(K14<>"",IF(K14>J14,K14-J14,""),$A$1-J14),"") | N14: =IF(OR(ISBLANK(K14),ISBLANK(N$5)),"",LET(_start,K14,_tat,N$5/24,_open,Config!$A$1,_close,Config!$A$2,_wd,Config!$A$3,_hol,Holidays!$A$1:$A$300,_sd,INT(_start),_st,MOD(_start,1),_iswd,_xlfn.WORKDAY.INTL(_sd-1,1,_wd,_hol)=_sd,_first,IF(_iswd,IF(_st<_open,_sd+_open,IF(_st>=_close,_xlfn.WORKDAY.INTL(_sd,1,_wd,_hol)+_open,_start)),_xlfn.WORKDAY.INTL(_sd,1,_wd,_hol)+_open),_ft,MOD(_first,1),_avail,_close - MAX(_ft,_open),IF(_tat<=_avail,_first + _tat,LET(_rem1,_tat - _avail,_daylen,_close - _open,_k,INT(_rem1/_daylen),_rem2,MOD(_rem1,_daylen),_base,_xlfn.WORKDAY.INTL(INT(_first),1+_k,_wd,_hol),IF(_rem2=0,_xlfn.WORKDAY.INTL(INT(_first),_k,_wd,_hol) + _close,_base + _open + _rem2))))) | Q14: =IF(N14,IF(O14<>"",IF(O14>N14,O14-N14,""),$A$1-N14),"") | R14: =IF(OR(ISBLANK(O14),ISBLANK(R$5)),"",LET(_start,O14,_tat,R$5/24,_open,Config!$A$1,_close,Config!$A$2,_wd,Config!$A$3,_hol,Holidays!$A$1:$A$300,_sd,INT(_start),_st,MOD(_start,1),_iswd,_xlfn.WORKDAY.INTL(_sd-1,1,_wd,_hol)=_sd,_first,IF(_iswd,IF(_st<_open,_sd+_open,IF(_st>=_close,_xlfn.WORKDAY.INTL(_sd,1,_wd,_hol)+_open,_start)),_xlfn.WORKDAY.INTL(_sd,1,_wd,_hol)+_open),_ft,MOD(_first,1),_avail,_close - MAX(_ft,_open),IF(_tat<=_avail,_first + _tat,LET(_rem1,_tat - _avail,_daylen,_close - _open,_k,INT(_rem1/_daylen),_rem2,MOD(_rem1,_daylen),_base,_xlfn.WORKDAY.INTL(INT(_first),1+_k,_wd,_hol),IF(_rem2=0,_xlfn.WORKDAY.INTL(INT(_first),_k,_wd,_hol) + _close,_base + _open + _rem2))))) | U14: =IF(R14,IF(S14<>"",IF(S14>R14,S14-R14,""),$A$1-R14),"") | V14: =IF(T14="Yes",IF(OR(ISBLANK(S14),ISBLANK(V$5)),"",LET(_start,S14,_tat,V$5/24,_open,Config!$A$1,_close,Config!$A$2,_wd,Config!$A$3,_hol,Holidays!$A$1:$A$300,_sd,INT(_start),_st,MOD(_start,1),_iswd,_xlfn.WORKDAY.INTL(_sd-1,1,_wd,_hol)=_sd,_first,IF(_iswd,IF(_st<_open,_sd+_open,IF(_st>=_close,_xlfn.WORKDAY.INTL(_sd,1,_wd,_hol)+_open,_start)),_xlfn.WORKDAY.INTL(_sd,1,_wd,_hol)+_open),_ft,MOD(_first,1),_avail,_close - MAX(_ft,_open),IF(_tat<=_avail,_first + _tat,LET(_rem1,_tat - _avail,_daylen,_close - _open,_k,INT(_rem1/_daylen),_rem2,MOD(_rem1,_daylen),_base,_xlfn.WORKDAY.INTL(INT(_first),1+_k,_wd,_hol),IF(_rem2=0,_xlfn.WORKDAY.INTL(INT(_first),_k,_wd,_hol) + _close,_base + _open + _rem2))))),"") | Y14: =IF(V14,IF(W14<>"",IF(W14>V14,W14-V14,""),$A$1-V14),"") | Z14: =IF(T14="No",IF(OR(ISBLANK(W14),ISBLANK(Z$5)),"",LET(_start,W14,_tat,Z$5/24,_open,Config!$A$1,_close,Config!$A$2,_wd,Config!$A$3,_hol,Holidays!$A$1:$A$300,_sd,INT(_start),_st,MOD(_start,1),_iswd,_xlfn.WORKDAY.INTL(_sd-1,1,_wd,_hol)=_sd,_first,IF(_iswd,IF(_st<_open,_sd+_open,IF(_st>=_close,_xlfn.WORKDAY.INTL(_sd,1,_wd,_hol)+_open,_start)),_xlfn.WORKDAY.INTL(_sd,1,_wd,_hol)+_open),_ft,MOD(_first,1),_avail,_close - MAX(_ft,_open),IF(_tat<=_avail,_first + _tat,LET(_rem1,_tat - _avail,_daylen,_close - _open,_k,INT(_rem1/_daylen),_rem2,MOD(_rem1,_daylen),_base,_xlfn.WORKDAY.INTL(INT(_first),1+_k,_wd,_hol),IF(_rem2=0,_xlfn.WORKDAY.INTL(INT(_first),_k,_wd,_hol) + _close,_base + _open + _rem2))))),"") | AC14: =IF(Z14,IF(AA14<>"",IF(AA14>Z14,AA14-Z14,""),$A$1-Z14),"")
F15: =IF(OR(ISBLANK(A15),ISBLANK(F$5)),"",LET(_start,A15,_tat,F$5/24,_open,Config!$A$1,_close,Config!$A$2,_wd,Config!$A$3,_hol,Holidays!$A$1:$A$300,_sd,INT(_start),_st,MOD(_start,1),_iswd,_xlfn.WORKDAY.INTL(_sd-1,1,_wd,_hol)=_sd,_first,IF(_iswd,IF(_st<_open,_sd+_open,IF(_st>=_close,_xlfn.WORKDAY.INTL(_sd,1,_wd,_hol)+_open,_start)),_xlfn.WORKDAY.INTL(_sd,1,_wd,_hol)+_open),_ft,MOD(_first,1),_avail,_close - MAX(_ft,_open),IF(_tat<=_avail,_first + _tat,LET(_rem1,_tat - _avail,_daylen,_close - _open,_k,INT(_rem1/_daylen),_rem2,MOD(_rem1,_daylen),_base,_xlfn.WORKDAY.INTL(INT(_first),1+_k,_wd,_hol),IF(_rem2=0,_xlfn.WORKDAY.INTL(INT(_first),_k,_wd,_hol) + _close,_base + _open + _rem2))))) | I15: =IF(F15,IF(G15<>"",IF(G15>F15,G15-F15,""),$A$1-F15),"") | J15: =IF(OR(ISBLANK(G15),ISBLANK(J$5)),"",LET(_start,G15,_tat,J$5/24,_open,Config!$A$1,_close,Config!$A$2,_wd,Config!$A$3,_hol,Holidays!$A$1:$A$300,_sd,INT(_start),_st,MOD(_start,1),_iswd,_xlfn.WORKDAY.INTL(_sd-1,1,_wd,_hol)=_sd,_first,IF(_iswd,IF(_st<_open,_sd+_open,IF(_st>=_close,_xlfn.WORKDAY.INTL(_sd,1,_wd,_hol)+_open,_start)),_xlfn.WORKDAY.INTL(_sd,1,_wd,_hol)+_open),_ft,MOD(_first,1),_avail,_close - MAX(_ft,_open),IF(_tat<=_avail,_first + _tat,LET(_rem1,_tat - _avail,_daylen,_close - _open,_k,INT(_rem1/_daylen),_rem2,MOD(_rem1,_daylen),_base,_xlfn.WORKDAY.INTL(INT(_first),1+_k,_wd,_hol),IF(_rem2=0,_xlfn.WORKDAY.INTL(INT(_first),_k,_wd,_hol) + _close,_base + _open + _rem2))))) | M15: =IF(J15,IF(K15<>"",IF(K15>J15,K15-J15,""),$A$1-J15),"") | N15: =IF(OR(ISBLANK(K15),ISBLANK(N$5)),"",LET(_start,K15,_tat,N$5/24,_open,Config!$A$1,_close,Config!$A$2,_wd,Config!$A$3,_hol,Holidays!$A$1:$A$300,_sd,INT(_start),_st,MOD(_start,1),_iswd,_xlfn.WORKDAY.INTL(_sd-1,1,_wd,_hol)=_sd,_first,IF(_iswd,IF(_st<_open,_sd+_open,IF(_st>=_close,_xlfn.WORKDAY.INTL(_sd,1,_wd,_hol)+_open,_start)),_xlfn.WORKDAY.INTL(_sd,1,_wd,_hol)+_open),_ft,MOD(_first,1),_avail,_close - MAX(_ft,_open),IF(_tat<=_avail,_first + _tat,LET(_rem1,_tat - _avail,_daylen,_close - _open,_k,INT(_rem1/_daylen),_rem2,MOD(_rem1,_daylen),_base,_xlfn.WORKDAY.INTL(INT(_first),1+_k,_wd,_hol),IF(_rem2=0,_xlfn.WORKDAY.INTL(INT(_first),_k,_wd,_hol) + _close,_base + _open + _rem2))))) | Q15: =IF(N15,IF(O15<>"",IF(O15>N15,O15-N15,""),$A$1-N15),"") | R15: =IF(OR(ISBLANK(O15),ISBLANK(R$5)),"",LET(_start,O15,_tat,R$5/24,_open,Config!$A$1,_close,Config!$A$2,_wd,Config!$A$3,_hol,Holidays!$A$1:$A$300,_sd,INT(_start),_st,MOD(_start,1),_iswd,_xlfn.WORKDAY.INTL(_sd-1,1,_wd,_hol)=_sd,_first,IF(_iswd,IF(_st<_open,_sd+_open,IF(_st>=_close,_xlfn.WORKDAY.INTL(_sd,1,_wd,_hol)+_open,_start)),_xlfn.WORKDAY.INTL(_sd,1,_wd,_hol)+_open),_ft,MOD(_first,1),_avail,_close - MAX(_ft,_open),IF(_tat<=_avail,_first + _tat,LET(_rem1,_tat - _avail,_daylen,_close - _open,_k,INT(_rem1/_daylen),_rem2,MOD(_rem1,_daylen),_base,_xlfn.WORKDAY.INTL(INT(_first),1+_k,_wd,_hol),IF(_rem2=0,_xlfn.WORKDAY.INTL(INT(_first),_k,_wd,_hol) + _close,_base + _open + _rem2))))) | U15: =IF(R15,IF(S15<>"",IF(S15>R15,S15-R15,""),$A$1-R15),"") | V15: =IF(T15="Yes",IF(OR(ISBLANK(S15),ISBLANK(V$5)),"",LET(_start,S15,_tat,V$5/24,_open,Config!$A$1,_close,Config!$A$2,_wd,Config!$A$3,_hol,Holidays!$A$1:$A$300,_sd,INT(_start),_st,MOD(_start,1),_iswd,_xlfn.WORKDAY.INTL(_sd-1,1,_wd,_hol)=_sd,_first,IF(_iswd,IF(_st<_open,_sd+_open,IF(_st>=_close,_xlfn.WORKDAY.INTL(_sd,1,_wd,_hol)+_open,_start)),_xlfn.WORKDAY.INTL(_sd,1,_wd,_hol)+_open),_ft,MOD(_first,1),_avail,_close - MAX(_ft,_open),IF(_tat<=_avail,_first + _tat,LET(_rem1,_tat - _avail,_daylen,_close - _open,_k,INT(_rem1/_daylen),_rem2,MOD(_rem1,_daylen),_base,_xlfn.WORKDAY.INTL(INT(_first),1+_k,_wd,_hol),IF(_rem2=0,_xlfn.WORKDAY.INTL(INT(_first),_k,_wd,_hol) + _close,_base + _open + _rem2))))),"") | Y15: =IF(V15,IF(W15<>"",IF(W15>V15,W15-V15,""),$A$1-V15),"") | Z15: =IF(T15="No",IF(OR(ISBLANK(W15),ISBLANK(Z$5)),"",LET(_start,W15,_tat,Z$5/24,_open,Config!$A$1,_close,Config!$A$2,_wd,Config!$A$3,_hol,Holidays!$A$1:$A$300,_sd,INT(_start),_st,MOD(_start,1),_iswd,_xlfn.WORKDAY.INTL(_sd-1,1,_wd,_hol)=_sd,_first,IF(_iswd,IF(_st<_open,_sd+_open,IF(_st>=_close,_xlfn.WORKDAY.INTL(_sd,1,_wd,_hol)+_open,_start)),_xlfn.WORKDAY.INTL(_sd,1,_wd,_hol)+_open),_ft,MOD(_first,1),_avail,_close - MAX(_ft,_open),IF(_tat<=_avail,_first + _tat,LET(_rem1,_tat - _avail,_daylen,_close - _open,_k,INT(_rem1/_daylen),_rem2,MOD(_rem1,_daylen),_base,_xlfn.WORKDAY.INTL(INT(_first),1+_k,_wd,_hol),IF(_rem2=0,_xlfn.WORKDAY.INTL(INT(_first),_k,_wd,_hol) + _close,_base + _open + _rem2))))),"") | AC15: =IF(Z15,IF(AA15<>"",IF(AA15>Z15,AA15-Z15,""),$A$1-Z15),"")
F16: =IF(OR(ISBLANK(A16),ISBLANK(F$5)),"",LET(_start,A16,_tat,F$5/24,_open,Config!$A$1,_close,Config!$A$2,_wd,Config!$A$3,_hol,Holidays!$A$1:$A$300,_sd,INT(_start),_st,MOD(_start,1),_iswd,_xlfn.WORKDAY.INTL(_sd-1,1,_wd,_hol)=_sd,_first,IF(_iswd,IF(_st<_open,_sd+_open,IF(_st>=_close,_xlfn.WORKDAY.INTL(_sd,1,_wd,_hol)+_open,_start)),_xlfn.WORKDAY.INTL(_sd,1,_wd,_hol)+_open),_ft,MOD(_first,1),_avail,_close - MAX(_ft,_open),IF(_tat<=_avail,_first + _tat,LET(_rem1,_tat - _avail,_daylen,_close - _open,_k,INT(_rem1/_daylen),_rem2,MOD(_rem1,_daylen),_base,_xlfn.WORKDAY.INTL(INT(_first),1+_k,_wd,_hol),IF(_rem2=0,_xlfn.WORKDAY.INTL(INT(_first),_k,_wd,_hol) + _close,_base + _open + _rem2))))) | I16: =IF(F16,IF(G16<>"",IF(G16>F16,G16-F16,""),$A$1-F16),"") | J16: =IF(OR(ISBLANK(G16),ISBLANK(J$5)),"",LET(_start,G16,_tat,J$5/24,_open,Config!$A$1,_close,Config!$A$2,_wd,Config!$A$3,_hol,Holidays!$A$1:$A$300,_sd,INT(_start),_st,MOD(_start,1),_iswd,_xlfn.WORKDAY.INTL(_sd-1,1,_wd,_hol)=_sd,_first,IF(_iswd,IF(_st<_open,_sd+_open,IF(_st>=_close,_xlfn.WORKDAY.INTL(_sd,1,_wd,_hol)+_open,_start)),_xlfn.WORKDAY.INTL(_sd,1,_wd,_hol)+_open),_ft,MOD(_first,1),_avail,_close - MAX(_ft,_open),IF(_tat<=_avail,_first + _tat,LET(_rem1,_tat - _avail,_daylen,_close - _open,_k,INT(_rem1/_daylen),_rem2,MOD(_rem1,_daylen),_base,_xlfn.WORKDAY.INTL(INT(_first),1+_k,_wd,_hol),IF(_rem2=0,_xlfn.WORKDAY.INTL(INT(_first),_k,_wd,_hol) + _close,_base + _open + _rem2))))) | M16: =IF(J16,IF(K16<>"",IF(K16>J16,K16-J16,""),$A$1-J16),"") | N16: =IF(OR(ISBLANK(K16),ISBLANK(N$5)),"",LET(_start,K16,_tat,N$5/24,_open,Config!$A$1,_close,Config!$A$2,_wd,Config!$A$3,_hol,Holidays!$A$1:$A$300,_sd,INT(_start),_st,MOD(_start,1),_iswd,_xlfn.WORKDAY.INTL(_sd-1,1,_wd,_hol)=_sd,_first,IF(_iswd,IF(_st<_open,_sd+_open,IF(_st>=_close,_xlfn.WORKDAY.INTL(_sd,1,_wd,_hol)+_open,_start)),_xlfn.WORKDAY.INTL(_sd,1,_wd,_hol)+_open),_ft,MOD(_first,1),_avail,_close - MAX(_ft,_open),IF(_tat<=_avail,_first + _tat,LET(_rem1,_tat - _avail,_daylen,_close - _open,_k,INT(_rem1/_daylen),_rem2,MOD(_rem1,_daylen),_base,_xlfn.WORKDAY.INTL(INT(_first),1+_k,_wd,_hol),IF(_rem2=0,_xlfn.WORKDAY.INTL(INT(_first),_k,_wd,_hol) + _close,_base + _open + _rem2))))) | Q16: =IF(N16,IF(O16<>"",IF(O16>N16,O16-N16,""),$A$1-N16),"") | R16: =IF(OR(ISBLANK(O16),ISBLANK(R$5)),"",LET(_start,O16,_tat,R$5/24,_open,Config!$A$1,_close,Config!$A$2,_wd,Config!$A$3,_hol,Holidays!$A$1:$A$300,_sd,INT(_start),_st,MOD(_start,1),_iswd,_xlfn.WORKDAY.INTL(_sd-1,1,_wd,_hol)=_sd,_first,IF(_iswd,IF(_st<_open,_sd+_open,IF(_st>=_close,_xlfn.WORKDAY.INTL(_sd,1,_wd,_hol)+_open,_start)),_xlfn.WORKDAY.INTL(_sd,1,_wd,_hol)+_open),_ft,MOD(_first,1),_avail,_close - MAX(_ft,_open),IF(_tat<=_avail,_first + _tat,LET(_rem1,_tat - _avail,_daylen,_close - _open,_k,INT(_rem1/_daylen),_rem2,MOD(_rem1,_daylen),_base,_xlfn.WORKDAY.INTL(INT(_first),1+_k,_wd,_hol),IF(_rem2=0,_xlfn.WORKDAY.INTL(INT(_first),_k,_wd,_hol) + _close,_base + _open + _rem2))))) | U16: =IF(R16,IF(S16<>"",IF(S16>R16,S16-R16,""),$A$1-R16),"") | V16: =IF(T16="Yes",IF(OR(ISBLANK(S16),ISBLANK(V$5)),"",LET(_start,S16,_tat,V$5/24,_open,Config!$A$1,_close,Config!$A$2,_wd,Config!$A$3,_hol,Holidays!$A$1:$A$300,_sd,INT(_start),_st,MOD(_start,1),_iswd,_xlfn.WORKDAY.INTL(_sd-1,1,_wd,_hol)=_sd,_first,IF(_iswd,IF(_st<_open,_sd+_open,IF(_st>=_close,_xlfn.WORKDAY.INTL(_sd,1,_wd,_hol)+_open,_start)),_xlfn.WORKDAY.INTL(_sd,1,_wd,_hol)+_open),_ft,MOD(_first,1),_avail,_close - MAX(_ft,_open),IF(_tat<=_avail,_first + _tat,LET(_rem1,_tat - _avail,_daylen,_close - _open,_k,INT(_rem1/_daylen),_rem2,MOD(_rem1,_daylen),_base,_xlfn.WORKDAY.INTL(INT(_first),1+_k,_wd,_hol),IF(_rem2=0,_xlfn.WORKDAY.INTL(INT(_first),_k,_wd,_hol) + _close,_base + _open + _rem2))))),"") | Y16: =IF(V16,IF(W16<>"",IF(W16>V16,W16-V16,""),$A$1-V16),"") | Z16: =IF(T16="No",IF(OR(ISBLANK(W16),ISBLANK(Z$5)),"",LET(_start,W16,_tat,Z$5/24,_open,Config!$A$1,_close,Config!$A$2,_wd,Config!$A$3,_hol,Holidays!$A$1:$A$300,_sd,INT(_start),_st,MOD(_start,1),_iswd,_xlfn.WORKDAY.INTL(_sd-1,1,_wd,_hol)=_sd,_first,IF(_iswd,IF(_st<_open,_sd+_open,IF(_st>=_close,_xlfn.WORKDAY.INTL(_sd,1,_wd,_hol)+_open,_start)),_xlfn.WORKDAY.INTL(_sd,1,_wd,_hol)+_open),_ft,MOD(_first,1),_avail,_close - MAX(_ft,_open),IF(_tat<=_avail,_first + _tat,LET(_rem1,_tat - _avail,_daylen,_close - _open,_k,INT(_rem1/_daylen),_rem2,MOD(_rem1,_daylen),_base,_xlfn.WORKDAY.INTL(INT(_first),1+_k,_wd,_hol),IF(_rem2=0,_xlfn.WORKDAY.INTL(INT(_first),_k,_wd,_hol) + _close,_base + _open + _rem2))))),"") | AC16: =IF(Z16,IF(AA16<>"",IF(AA16>Z16,AA16-Z16,""),$A$1-Z16),"")
F17: =IF(OR(ISBLANK(A17),ISBLANK(F$5)),"",LET(_start,A17,_tat,F$5/24,_open,Config!$A$1,_close,Config!$A$2,_wd,Config!$A$3,_hol,Holidays!$A$1:$A$300,_sd,INT(_start),_st,MOD(_start,1),_iswd,_xlfn.WORKDAY.INTL(_sd-1,1,_wd,_hol)=_sd,_first,IF(_iswd,IF(_st<_open,_sd+_open,IF(_st>=_close,_xlfn.WORKDAY.INTL(_sd,1,_wd,_hol)+_open,_start)),_xlfn.WORKDAY.INTL(_sd,1,_wd,_hol)+_open),_ft,MOD(_first,1),_avail,_close - MAX(_ft,_open),IF(_tat<=_avail,_first + _tat,LET(_rem1,_tat - _avail,_daylen,_close - _open,_k,INT(_rem1/_daylen),_rem2,MOD(_rem1,_daylen),_base,_xlfn.WORKDAY.INTL(INT(_first),1+_k,_wd,_hol),IF(_rem2=0,_xlfn.WORKDAY.INTL(INT(_first),_k,_wd,_hol) + _close,_base + _open + _rem2))))) | I17: =IF(F17,IF(G17<>"",IF(G17>F17,G17-F17,""),$A$1-F17),"") | J17: =IF(OR(ISBLANK(G17),ISBLANK(J$5)),"",LET(_start,G17,_tat,J$5/24,_open,Config!$A$1,_close,Config!$A$2,_wd,Config!$A$3,_hol,Holidays!$A$1:$A$300,_sd,INT(_start),_st,MOD(_start,1),_iswd,_xlfn.WORKDAY.INTL(_sd-1,1,_wd,_hol)=_sd,_first,IF(_iswd,IF(_st<_open,_sd+_open,IF(_st>=_close,_xlfn.WORKDAY.INTL(_sd,1,_wd,_hol)+_open,_start)),_xlfn.WORKDAY.INTL(_sd,1,_wd,_hol)+_open),_ft,MOD(_first,1),_avail,_close - MAX(_ft,_open),IF(_tat<=_avail,_first + _tat,LET(_rem1,_tat - _avail,_daylen,_close - _open,_k,INT(_rem1/_daylen),_rem2,MOD(_rem1,_daylen),_base,_xlfn.WORKDAY.INTL(INT(_first),1+_k,_wd,_hol),IF(_rem2=0,_xlfn.WORKDAY.INTL(INT(_first),_k,_wd,_hol) + _close,_base + _open + _rem2))))) | M17: =IF(J17,IF(K17<>"",IF(K17>J17,K17-J17,""),$A$1-J17),"") | N17: =IF(OR(ISBLANK(K17),ISBLANK(N$5)),"",LET(_start,K17,_tat,N$5/24,_open,Config!$A$1,_close,Config!$A$2,_wd,Config!$A$3,_hol,Holidays!$A$1:$A$300,_sd,INT(_start),_st,MOD(_start,1),_iswd,_xlfn.WORKDAY.INTL(_sd-1,1,_wd,_hol)=_sd,_first,IF(_iswd,IF(_st<_open,_sd+_open,IF(_st>=_close,_xlfn.WORKDAY.INTL(_sd,1,_wd,_hol)+_open,_start)),_xlfn.WORKDAY.INTL(_sd,1,_wd,_hol)+_open),_ft,MOD(_first,1),_avail,_close - MAX(_ft,_open),IF(_tat<=_avail,_first + _tat,LET(_rem1,_tat - _avail,_daylen,_close - _open,_k,INT(_rem1/_daylen),_rem2,MOD(_rem1,_daylen),_base,_xlfn.WORKDAY.INTL(INT(_first),1+_k,_wd,_hol),IF(_rem2=0,_xlfn.WORKDAY.INTL(INT(_first),_k,_wd,_hol) + _close,_base + _open + _rem2))))) | Q17: =IF(N17,IF(O17<>"",IF(O17>N17,O17-N17,""),$A$1-N17),"") | R17: =IF(OR(ISBLANK(O17),ISBLANK(R$5)),"",LET(_start,O17,_tat,R$5/24,_open,Config!$A$1,_close,Config!$A$2,_wd,Config!$A$3,_hol,Holidays!$A$1:$A$300,_sd,INT(_start),_st,MOD(_start,1),_iswd,_xlfn.WORKDAY.INTL(_sd-1,1,_wd,_hol)=_sd,_first,IF(_iswd,IF(_st<_open,_sd+_open,IF(_st>=_close,_xlfn.WORKDAY.INTL(_sd,1,_wd,_hol)+_open,_start)),_xlfn.WORKDAY.INTL(_sd,1,_wd,_hol)+_open),_ft,MOD(_first,1),_avail,_close - MAX(_ft,_open),IF(_tat<=_avail,_first + _tat,LET(_rem1,_tat - _avail,_daylen,_close - _open,_k,INT(_rem1/_daylen),_rem2,MOD(_rem1,_daylen),_base,_xlfn.WORKDAY.INTL(INT(_first),1+_k,_wd,_hol),IF(_rem2=0,_xlfn.WORKDAY.INTL(INT(_first),_k,_wd,_hol) + _close,_base + _open + _rem2))))) | U17: =IF(R17,IF(S17<>"",IF(S17>R17,S17-R17,""),$A$1-R17),"") | V17: =IF(T17="Yes",IF(OR(ISBLANK(S17),ISBLANK(V$5)),"",LET(_start,S17,_tat,V$5/24,_open,Config!$A$1,_close,Config!$A$2,_wd,Config!$A$3,_hol,Holidays!$A$1:$A$300,_sd,INT(_start),_st,MOD(_start,1),_iswd,_xlfn.WORKDAY.INTL(_sd-1,1,_wd,_hol)=_sd,_first,IF(_iswd,IF(_st<_open,_sd+_open,IF(_st>=_close,_xlfn.WORKDAY.INTL(_sd,1,_wd,_hol)+_open,_start)),_xlfn.WORKDAY.INTL(_sd,1,_wd,_hol)+_open),_ft,MOD(_first,1),_avail,_close - MAX(_ft,_open),IF(_tat<=_avail,_first + _tat,LET(_rem1,_tat - _avail,_daylen,_close - _open,_k,INT(_rem1/_daylen),_rem2,MOD(_rem1,_daylen),_base,_xlfn.WORKDAY.INTL(INT(_first),1+_k,_wd,_hol),IF(_rem2=0,_xlfn.WORKDAY.INTL(INT(_first),_k,_wd,_hol) + _close,_base + _open + _rem2))))),"") | Y17: =IF(V17,IF(W17<>"",IF(W17>V17,W17-V17,""),$A$1-V17),"") | Z17: =IF(T17="No",IF(OR(ISBLANK(W17),ISBLANK(Z$5)),"",LET(_start,W17,_tat,Z$5/24,_open,Config!$A$1,_close,Config!$A$2,_wd,Config!$A$3,_hol,Holidays!$A$1:$A$300,_sd,INT(_start),_st,MOD(_start,1),_iswd,_xlfn.WORKDAY.INTL(_sd-1,1,_wd,_hol)=_sd,_first,IF(_iswd,IF(_st<_open,_sd+_open,IF(_st>=_close,_xlfn.WORKDAY.INTL(_sd,1,_wd,_hol)+_open,_start)),_xlfn.WORKDAY.INTL(_sd,1,_wd,_hol)+_open),_ft,MOD(_first,1),_avail,_close - MAX(_ft,_open),IF(_tat<=_avail,_first + _tat,LET(_rem1,_tat - _avail,_daylen,_close - _open,_k,INT(_rem1/_daylen),_rem2,MOD(_rem1,_daylen),_base,_xlfn.WORKDAY.INTL(INT(_first),1+_k,_wd,_hol),IF(_rem2=0,_xlfn.WORKDAY.INTL(INT(_first),_k,_wd,_hol) + _close,_base + _open + _rem2))))),"") | AC17: =IF(Z17,IF(AA17<>"",IF(AA17>Z17,AA17-Z17,""),$A$1-Z17),"")
F18: =IF(OR(ISBLANK(A18),ISBLANK(F$5)),"",LET(_start,A18,_tat,F$5/24,_open,Config!$A$1,_close,Config!$A$2,_wd,Config!$A$3,_hol,Holidays!$A$1:$A$300,_sd,INT(_start),_st,MOD(_start,1),_iswd,_xlfn.WORKDAY.INTL(_sd-1,1,_wd,_hol)=_sd,_first,IF(_iswd,IF(_st<_open,_sd+_open,IF(_st>=_close,_xlfn.WORKDAY.INTL(_sd,1,_wd,_hol)+_open,_start)),_xlfn.WORKDAY.INTL(_sd,1,_wd,_hol)+_open),_ft,MOD(_first,1),_avail,_close - MAX(_ft,_open),IF(_tat<=_avail,_first + _tat,LET(_rem1,_tat - _avail,_daylen,_close - _open,_k,INT(_rem1/_daylen),_rem2,MOD(_rem1,_daylen),_base,_xlfn.WORKDAY.INTL(INT(_first),1+_k,_wd,_hol),IF(_rem2=0,_xlfn.WORKDAY.INTL(INT(_first),_k,_wd,_hol) + _close,_base + _open + _rem2))))) | I18: =IF(F18,IF(G18<>"",IF(G18>F18,G18-F18,""),$A$1-F18),"") | J18: =IF(OR(ISBLANK(G18),ISBLANK(J$5)),"",LET(_start,G18,_tat,J$5/24,_open,Config!$A$1,_close,Config!$A$2,_wd,Config!$A$3,_hol,Holidays!$A$1:$A$300,_sd,INT(_start),_st,MOD(_start,1),_iswd,_xlfn.WORKDAY.INTL(_sd-1,1,_wd,_hol)=_sd,_first,IF(_iswd,IF(_st<_open,_sd+_open,IF(_st>=_close,_xlfn.WORKDAY.INTL(_sd,1,_wd,_hol)+_open,_start)),_xlfn.WORKDAY.INTL(_sd,1,_wd,_hol)+_open),_ft,MOD(_first,1),_avail,_close - MAX(_ft,_open),IF(_tat<=_avail,_first + _tat,LET(_rem1,_tat - _avail,_daylen,_close - _open,_k,INT(_rem1/_daylen),_rem2,MOD(_rem1,_daylen),_base,_xlfn.WORKDAY.INTL(INT(_first),1+_k,_wd,_hol),IF(_rem2=0,_xlfn.WORKDAY.INTL(INT(_first),_k,_wd,_hol) + _close,_base + _open + _rem2))))) | M18: =IF(J18,IF(K18<>"",IF(K18>J18,K18-J18,""),$A$1-J18),"") | N18: =IF(OR(ISBLANK(K18),ISBLANK(N$5)),"",LET(_start,K18,_tat,N$5/24,_open,Config!$A$1,_close,Config!$A$2,_wd,Config!$A$3,_hol,Holidays!$A$1:$A$300,_sd,INT(_start),_st,MOD(_start,1),_iswd,_xlfn.WORKDAY.INTL(_sd-1,1,_wd,_hol)=_sd,_first,IF(_iswd,IF(_st<_open,_sd+_open,IF(_st>=_close,_xlfn.WORKDAY.INTL(_sd,1,_wd,_hol)+_open,_start)),_xlfn.WORKDAY.INTL(_sd,1,_wd,_hol)+_open),_ft,MOD(_first,1),_avail,_close - MAX(_ft,_open),IF(_tat<=_avail,_first + _tat,LET(_rem1,_tat - _avail,_daylen,_close - _open,_k,INT(_rem1/_daylen),_rem2,MOD(_rem1,_daylen),_base,_xlfn.WORKDAY.INTL(INT(_first),1+_k,_wd,_hol),IF(_rem2=0,_xlfn.WORKDAY.INTL(INT(_first),_k,_wd,_hol) + _close,_base + _open + _rem2))))) | Q18: =IF(N18,IF(O18<>"",IF(O18>N18,O18-N18,""),$A$1-N18),"") | R18: =IF(OR(ISBLANK(O18),ISBLANK(R$5)),"",LET(_start,O18,_tat,R$5/24,_open,Config!$A$1,_close,Config!$A$2,_wd,Config!$A$3,_hol,Holidays!$A$1:$A$300,_sd,INT(_start),_st,MOD(_start,1),_iswd,_xlfn.WORKDAY.INTL(_sd-1,1,_wd,_hol)=_sd,_first,IF(_iswd,IF(_st<_open,_sd+_open,IF(_st>=_close,_xlfn.WORKDAY.INTL(_sd,1,_wd,_hol)+_open,_start)),_xlfn.WORKDAY.INTL(_sd,1,_wd,_hol)+_open),_ft,MOD(_first,1),_avail,_close - MAX(_ft,_open),IF(_tat<=_avail,_first + _tat,LET(_rem1,_tat - _avail,_daylen,_close - _open,_k,INT(_rem1/_daylen),_rem2,MOD(_rem1,_daylen),_base,_xlfn.WORKDAY.INTL(INT(_first),1+_k,_wd,_hol),IF(_rem2=0,_xlfn.WORKDAY.INTL(INT(_first),_k,_wd,_hol) + _close,_base + _open + _rem2))))) | U18: =IF(R18,IF(S18<>"",IF(S18>R18,S18-R18,""),$A$1-R18),"") | V18: =IF(T18="Yes",IF(OR(ISBLANK(S18),ISBLANK(V$5)),"",LET(_start,S18,_tat,V$5/24,_open,Config!$A$1,_close,Config!$A$2,_wd,Config!$A$3,_hol,Holidays!$A$1:$A$300,_sd,INT(_start),_st,MOD(_start,1),_iswd,_xlfn.WORKDAY.INTL(_sd-1,1,_wd,_hol)=_sd,_first,IF(_iswd,IF(_st<_open,_sd+_open,IF(_st>=_close,_xlfn.WORKDAY.INTL(_sd,1,_wd,_hol)+_open,_start)),_xlfn.WORKDAY.INTL(_sd,1,_wd,_hol)+_open),_ft,MOD(_first,1),_avail,_close - MAX(_ft,_open),IF(_tat<=_avail,_first + _tat,LET(_rem1,_tat - _avail,_daylen,_close - _open,_k,INT(_rem1/_daylen),_rem2,MOD(_rem1,_daylen),_base,_xlfn.WORKDAY.INTL(INT(_first),1+_k,_wd,_hol),IF(_rem2=0,_xlfn.WORKDAY.INTL(INT(_first),_k,_wd,_hol) + _close,_base + _open + _rem2))))),"") | Y18: =IF(V18,IF(W18<>"",IF(W18>V18,W18-V18,""),$A$1-V18),"") | Z18: =IF(T18="No",IF(OR(ISBLANK(W18),ISBLANK(Z$5)),"",LET(_start,W18,_tat,Z$5/24,_open,Config!$A$1,_close,Config!$A$2,_wd,Config!$A$3,_hol,Holidays!$A$1:$A$300,_sd,INT(_start),_st,MOD(_start,1),_iswd,_xlfn.WORKDAY.INTL(_sd-1,1,_wd,_hol)=_sd,_first,IF(_iswd,IF(_st<_open,_sd+_open,IF(_st>=_close,_xlfn.WORKDAY.INTL(_sd,1,_wd,_hol)+_open,_start)),_xlfn.WORKDAY.INTL(_sd,1,_wd,_hol)+_open),_ft,MOD(_first,1),_avail,_close - MAX(_ft,_open),IF(_tat<=_avail,_first + _tat,LET(_rem1,_tat - _avail,_daylen,_close - _open,_k,INT(_rem1/_daylen),_rem2,MOD(_rem1,_daylen),_base,_xlfn.WORKDAY.INTL(INT(_first),1+_k,_wd,_hol),IF(_rem2=0,_xlfn.WORKDAY.INTL(INT(_first),_k,_wd,_hol) + _close,_base + _open + _rem2))))),"") | AC18: =IF(Z18,IF(AA18<>"",IF(AA18>Z18,AA18-Z18,""),$A$1-Z18),"")
